// Você viu no exemplo anterior que nem sempre a operação assíncrona será executada com sucesso. Por esse motivo, é importante manter uma boa cobertura de testes a fim de prevenir possíveis erros. Para isso, você irá utilizar o Jest. Caso não se lembre de como instalar e iniciar o Jest, reveja este bloco antes de começar a colocar a mão na massa.
// Ao realizar testes assíncronos com callbacks, é necessário ter cuidado com falso-positivo (quando o teste deveria falhar mas acaba passando). Isso acontece pois o Jest não sabe, por padrão, quando é necessário esperar o término da execução de uma função assíncrona. Ou seja, você roda o teste, o Jest analisa as funções síncronas, não espera as assíncronas terminarem e, dado o final do teste, gera um resultado positivo antes de um eventual problema numa função assíncrona acusar um erro.
// O exemplo abaixo gera um falso-positivo:
// Copiar
// test('Não deveria passar!', () => {
//   setTimeout(() => {
//     expect(10).toBe(5);
//     console.log('Deveria falhar!');
//   }, 500);
// });
// Copie o código acima em um arquivo .test.js e execute o comando npm test na sua máquina para ver! Como o setTimeout é uma função assíncrona, o teste retorna um resultado falso-positivo quando executado dessa forma — note, inclusive, que a frase "Deveria falhar!" sequer aparece no console.
// Para que o Jest espere a função assíncrona ser finalizada, é necessário utilizar uma callback própria da biblioteca, chamada done , que precisa ser chamada após os testes assíncronos.
// Vamos reescrever o teste chamando a callback done após a asserção para indicar que o teste acabou: O termo asserção é a verificação realizada pelo Jest para saber se um valor atende alguma condição
// Copiar
// test('Não deveria passar!', (done) => {
//   setTimeout(() => {
//     expect(10).toBe(5);
//     console.log('Deveria falhar!');
//     done();
//   }, 500);
// });
// Apesar do código acima parecer correto, irá falhar com uma mensagem de timeout. O motivo é que quando uma asserção (verificação) falha, a exceção é lançada, ou seja, algo inesperado aconteceu. Dessa forma, o fluxo é interrompido antes que a instrução done() seja executada. Para resolver este problema podemos colocar um bloco try/catch em volta da nossa asserção. Enquanto o try tenta executar a função no seu escopo com sucesso, o catch "captura" o erro, chamando a callback done :
// Copiar
// test('Não deveria passar!', (done) => {
//   setTimeout(() => {
//     try {
//       expect(10).toBe(5);
//       console.log('Deveria falhar!');
//       done();
//     } catch (error) {
//       done();
//     }
//   }, 500);
// });
// Estamos quase lá... O código acima irá gerar um falso-positivo. O motivo é que não estamos passando nenhuma ação a ser realizada quando o erro acontece e "encerramos" nosso teste com o done() sem lançar nenhum erro, dessa forma o teste é interpretado como "correto". Para resolver, podemos passar o parâmetro de erro para o catch . Dessa forma, caso nosso try não consiga executar o código dentro dele, cairá no catch , que vai pegar esse erro e vai encerrar nosso teste lançando um erro.
// Copiar
// test('Não deveria passar!', (done) => {
//   setTimeout(() => {
//     try {
//       expect(10).toBe(5);
//       console.log('Deveria falhar!');
//       done();
//     } catch (error) {
//       done(error); // Alteramos esta linha
//     }
//   }, 500);
// });
// Agora sim, nosso teste falhou! Isso significa que você conseguiu testar com sucesso a callback.
// Vamos a mais um exemplo para fixação, desta vez você irá implementar uma função que espera um tempo e retorna a soma de dois números:
// Copiar
// const asyncSum = (a, b, callback) => {
//   setTimeout(() => {
//     const result = a + b;
//     callback(result);
//   }, 500);
// };

// test('Testando asyncSum, soma 5 mais 10', (done) => {
//   asyncSum(5, 10, (result) => {
//     try {
//       expect(result).toBe(15);
//       done();
//     } catch (error) {
//       done(error);
//     }
//   });
// });
// Quando estiver realizando testes, é muito importante verificar se os resultados exibidos não são falso-positivos. No exemplo acima, em que o teste está passando, experimente mudar a implementação da função asyncSum para que retorne valores incorretos e verifique se o teste irá falhar. Por exemplo, se mudarmos os resultado para ser a + b + 1 o teste falha dizendo que esperava 15 , mas recebeu 16 .
// Não se preocupe, vamos treinar bastante! Agora, vamos para o próximo tópico \o/
// Acredite, vai ser muito útil pois você vai conseguir economizar tempo e código ;)
